<mujoco model="firefighter">
    <compiler angle="radian" meshdir="../meshes_mujoco/" />
    <size njmax="500" nconmax="100" />
    <asset>
        <mesh name="base" file="base.stl" />
        <mesh name="joint1" file="joint1.stl" />
        <mesh name="joint2" file="joint2.stl" />
        <mesh name="joint3" file="joint3.stl" />
        <mesh name="joint4" file="joint4.stl" />
        <mesh name="joint5" file="joint5.stl" />
        <mesh name="joint6" file="joint6.stl" />
        <mesh name="joint7" file="joint7.stl" />
    </asset>
    <worldbody>
        <geom type="mesh" contype="0" conaffinity="0" group="1" mesh="base" />
        <geom type="mesh" mesh="base" />
        <body name="joint1" pos="0 0 99">
            <inertial pos="-0.779106 -2.36462e-05 58.4904" quat="0.999969 8.6787e-06 0.00790243 4.0482e-06" mass="4.01213e+08" diaginertia="5.70624e+11 4.22606e+11 3.02666e+11" />
            <joint name="joint1_to_base" pos="0 0 0" axis="0 0 1" limited="true" range="-3.1 3.1" />
            <geom pos="0 0 -0.08" type="mesh" contype="0" conaffinity="0" group="1" mesh="joint1" />
            <geom pos="0 0 -0.08" type="mesh" mesh="joint1" />
            <body name="joint2" pos="0 0 80" quat="0.707105 -0.707108 0 0">
                <inertial pos="-0.277417 -70.1136 -2.88245e-05" quat="0.499311 0.500689 -0.49931 0.500688" mass="4.13119e+08" diaginertia="1.07166e+12 1.04682e+12 1.70944e+11" />
                <joint name="joint2_to_joint1" pos="0 0 0" axis="0 0 1" limited="true" range="-1.42 2.26" />
                <geom quat="9.38184e-07 0.707105 -0.707108 -9.38187e-07" type="mesh" contype="0" conaffinity="0" group="1" mesh="joint2" />
                <geom quat="9.38184e-07 0.707105 -0.707108 -9.38187e-07" type="mesh" mesh="joint2" />
                <body name="joint3" pos="0 -125 0" quat="0.707105 0.707108 0 0">
                    <inertial pos="17.5987 -8.8179e-05 44.3613" quat="0.932342 8.21665e-06 0.361579 7.81415e-07" mass="3.59824e+08" diaginertia="4.38894e+11 3.01399e+11 2.82728e+11" />
                    <joint name="joint3_to_joint2" pos="0 0 0" axis="0 0 1" limited="true" range="-3.1 3.1" />
                    <geom pos="0 0 0.038" type="mesh" contype="0" conaffinity="0" group="1" mesh="joint3" />
                    <geom pos="0 0 0.038" type="mesh" mesh="joint3" />
                    <body name="joint4" pos="30 0 58" quat="9.38184e-07 -9.38187e-07 -0.707108 0.707105">
                        <inertial pos="15.8364 -16.2784 0.00081027" quat="0.296941 0.641726 -0.296949 0.641744" mass="1.79594e+08" diaginertia="1.72156e+11 1.50613e+11 6.14322e+10" />
                        <joint name="joint4_to_joint3" pos="0 0 0" axis="0 0 1" limited="true" range="-3.0543 0.2617" />
                        <geom quat="0.707105 0 0 -0.707108" type="mesh" contype="0" conaffinity="0" group="1" mesh="joint4" />
                        <geom quat="0.707105 0 0 -0.707108" type="mesh" mesh="joint4" />
                        <body name="joint5" pos="30 -56 0" quat="9.38184e-07 9.38187e-07 0.707105 -0.707108">
                            <inertial pos="-8.69605e-05 10.1793 73.1766" quat="0.990747 -0.135723 -1.10623e-06 -1.28904e-06" mass="3.06707e+08" diaginertia="6.58582e+11 6.52921e+11 1.02085e+11" />
                            <joint name="joint5_to_joint4" pos="0 0 0" axis="0 0 1" limited="true" range="-3.1 3.1" />
                            <geom pos="0 0 -0.069" type="mesh" contype="0" conaffinity="0" group="1" mesh="joint5" />
                            <geom pos="0 0 -0.069" type="mesh" mesh="joint5" />
                            <body name="joint6" pos="0 25 150" quat="0.707105 0.707108 0 0">
                                <inertial pos="22.6284 0.64977 26.8628" quat="-0.0344706 0.756414 0.0294201 0.652521" mass="2.77749e+08" diaginertia="2.58265e+11 1.95301e+11 1.78199e+11" />
                                <joint name="joint6_to_joint5" pos="0 0 0" axis="0 0 1" limited="true" range="-0.0349 2.9321" />
                                <geom pos="0 0 -0.025" quat="0.707105 0 0 -0.707108" type="mesh" contype="0" conaffinity="0" group="1" mesh="joint6" />
                                <geom pos="0 0 -0.025" quat="0.707105 0 0 -0.707108" type="mesh" mesh="joint6" />
                                <body name="joint7" pos="38 -43 25" quat="0.707105 0.707108 0 0">
                                    <inertial pos="-4.21473e-08 -1.03456e-08 2.748" quat="0.570522 0.417738 -0.570522 0.417738" mass="1.02958e+07" diaginertia="3.21225e+09 1.63208e+09 1.63208e+09" />
                                    <joint name="joint7_to_joint6" pos="0 0 0" axis="0 0 1" limited="true" range="-3.1 3.1" />
                                    <geom pos="0 0 -0.002" quat="0.707105 0 0 -0.707108" type="mesh" contype="0" conaffinity="0" group="1" mesh="joint7" />
                                    <geom pos="0 0 -0.002" quat="0.707105 0 0 -0.707108" type="mesh" mesh="joint7" />
                                </body>
                            </body>
                        </body>
                    </body>
                </body>
            </body>
        </body>
    </worldbody>
</mujoco>
